Traceback (most recent call last):
  File "/opt/hostedtoolcache/Python/3.11.9/x64/lib/python3.11/site-packages/jupyter_cache/executors/utils.py", line 58, in single_nb_execution
    executenb(
  File "/opt/hostedtoolcache/Python/3.11.9/x64/lib/python3.11/site-packages/nbclient/client.py", line 1314, in execute
    return NotebookClient(nb=nb, resources=resources, km=km, **kwargs).execute()
           ^^^^^^^^^^^^^^^^^^^^^^^^^^^^^^^^^^^^^^^^^^^^^^^^^^^^^^^^^^^^^^^^^^^^^
  File "/opt/hostedtoolcache/Python/3.11.9/x64/lib/python3.11/site-packages/jupyter_core/utils/__init__.py", line 165, in wrapped
    return loop.run_until_complete(inner)
           ^^^^^^^^^^^^^^^^^^^^^^^^^^^^^^
  File "/opt/hostedtoolcache/Python/3.11.9/x64/lib/python3.11/asyncio/base_events.py", line 654, in run_until_complete
    return future.result()
           ^^^^^^^^^^^^^^^
  File "/opt/hostedtoolcache/Python/3.11.9/x64/lib/python3.11/site-packages/nbclient/client.py", line 709, in async_execute
    await self.async_execute_cell(
  File "/opt/hostedtoolcache/Python/3.11.9/x64/lib/python3.11/site-packages/nbclient/client.py", line 1062, in async_execute_cell
    await self._check_raise_for_error(cell, cell_index, exec_reply)
  File "/opt/hostedtoolcache/Python/3.11.9/x64/lib/python3.11/site-packages/nbclient/client.py", line 918, in _check_raise_for_error
    raise CellExecutionError.from_cell_and_msg(cell, exec_reply_content)
nbclient.exceptions.CellExecutionError: An error occurred while executing the following cell:
------------------
from particula.util import friction_factor
help(friction_factor)
------------------


[0;31m---------------------------------------------------------------------------[0m
[0;31mFileNotFoundError[0m                         Traceback (most recent call last)
File [0;32m/opt/hostedtoolcache/Python/3.11.9/x64/lib/python3.11/logging/config.py:573[0m, in [0;36mDictConfigurator.configure[0;34m(self)[0m
[1;32m    572[0m [38;5;28;01mtry[39;00m:
[0;32m--> 573[0m     handler [38;5;241m=[39m [38;5;28;43mself[39;49m[38;5;241;43m.[39;49m[43mconfigure_handler[49m[43m([49m[43mhandlers[49m[43m[[49m[43mname[49m[43m][49m[43m)[49m
[1;32m    574[0m     handler[38;5;241m.[39mname [38;5;241m=[39m name

File [0;32m/opt/hostedtoolcache/Python/3.11.9/x64/lib/python3.11/logging/config.py:757[0m, in [0;36mDictConfigurator.configure_handler[0;34m(self, config)[0m
[1;32m    756[0m [38;5;28;01mtry[39;00m:
[0;32m--> 757[0m     result [38;5;241m=[39m [43mfactory[49m[43m([49m[38;5;241;43m*[39;49m[38;5;241;43m*[39;49m[43mkwargs[49m[43m)[49m
[1;32m    758[0m [38;5;28;01mexcept[39;00m [38;5;167;01mTypeError[39;00m [38;5;28;01mas[39;00m te:

File [0;32m/opt/hostedtoolcache/Python/3.11.9/x64/lib/python3.11/logging/handlers.py:155[0m, in [0;36mRotatingFileHandler.__init__[0;34m(self, filename, mode, maxBytes, backupCount, encoding, delay, errors)[0m
[1;32m    154[0m     encoding [38;5;241m=[39m io[38;5;241m.[39mtext_encoding(encoding)
[0;32m--> 155[0m [43mBaseRotatingHandler[49m[38;5;241;43m.[39;49m[38;5;21;43m__init__[39;49m[43m([49m[38;5;28;43mself[39;49m[43m,[49m[43m [49m[43mfilename[49m[43m,[49m[43m [49m[43mmode[49m[43m,[49m[43m [49m[43mencoding[49m[38;5;241;43m=[39;49m[43mencoding[49m[43m,[49m
[1;32m    156[0m [43m                             [49m[43mdelay[49m[38;5;241;43m=[39;49m[43mdelay[49m[43m,[49m[43m [49m[43merrors[49m[38;5;241;43m=[39;49m[43merrors[49m[43m)[49m
[1;32m    157[0m [38;5;28mself[39m[38;5;241m.[39mmaxBytes [38;5;241m=[39m maxBytes

File [0;32m/opt/hostedtoolcache/Python/3.11.9/x64/lib/python3.11/logging/handlers.py:58[0m, in [0;36mBaseRotatingHandler.__init__[0;34m(self, filename, mode, encoding, delay, errors)[0m
[1;32m     55[0m [38;5;250m[39m[38;5;124;03m"""[39;00m
[1;32m     56[0m [38;5;124;03mUse the specified filename for streamed logging[39;00m
[1;32m     57[0m [38;5;124;03m"""[39;00m
[0;32m---> 58[0m [43mlogging[49m[38;5;241;43m.[39;49m[43mFileHandler[49m[38;5;241;43m.[39;49m[38;5;21;43m__init__[39;49m[43m([49m[38;5;28;43mself[39;49m[43m,[49m[43m [49m[43mfilename[49m[43m,[49m[43m [49m[43mmode[49m[38;5;241;43m=[39;49m[43mmode[49m[43m,[49m
[1;32m     59[0m [43m                             [49m[43mencoding[49m[38;5;241;43m=[39;49m[43mencoding[49m[43m,[49m[43m [49m[43mdelay[49m[38;5;241;43m=[39;49m[43mdelay[49m[43m,[49m
[1;32m     60[0m [43m                             [49m[43merrors[49m[38;5;241;43m=[39;49m[43merrors[49m[43m)[49m
[1;32m     61[0m [38;5;28mself[39m[38;5;241m.[39mmode [38;5;241m=[39m mode

File [0;32m/opt/hostedtoolcache/Python/3.11.9/x64/lib/python3.11/logging/__init__.py:1181[0m, in [0;36mFileHandler.__init__[0;34m(self, filename, mode, encoding, delay, errors)[0m
[1;32m   1180[0m [38;5;28;01melse[39;00m:
[0;32m-> 1181[0m     StreamHandler[38;5;241m.[39m[38;5;21m__init__[39m([38;5;28mself[39m, [38;5;28;43mself[39;49m[38;5;241;43m.[39;49m[43m_open[49m[43m([49m[43m)[49m)

File [0;32m/opt/hostedtoolcache/Python/3.11.9/x64/lib/python3.11/logging/__init__.py:1213[0m, in [0;36mFileHandler._open[0;34m(self)[0m
[1;32m   1212[0m open_func [38;5;241m=[39m [38;5;28mself[39m[38;5;241m.[39m_builtin_open
[0;32m-> 1213[0m [38;5;28;01mreturn[39;00m [43mopen_func[49m[43m([49m[38;5;28;43mself[39;49m[38;5;241;43m.[39;49m[43mbaseFilename[49m[43m,[49m[43m [49m[38;5;28;43mself[39;49m[38;5;241;43m.[39;49m[43mmode[49m[43m,[49m
[1;32m   1214[0m [43m                 [49m[43mencoding[49m[38;5;241;43m=[39;49m[38;5;28;43mself[39;49m[38;5;241;43m.[39;49m[43mencoding[49m[43m,[49m[43m [49m[43merrors[49m[38;5;241;43m=[39;49m[38;5;28;43mself[39;49m[38;5;241;43m.[39;49m[43merrors[49m[43m)[49m

[0;31mFileNotFoundError[0m: [Errno 2] No such file or directory: '/opt/hostedtoolcache/Python/3.11.9/x64/lib/python3.11/site-packages/particula/logging/particula.log'

The above exception was the direct cause of the following exception:

[0;31mValueError[0m                                Traceback (most recent call last)
Cell [0;32mIn[1], line 1[0m
[0;32m----> 1[0m [38;5;28;01mfrom[39;00m [38;5;21;01mparticula[39;00m[38;5;21;01m.[39;00m[38;5;21;01mutil[39;00m [38;5;28;01mimport[39;00m friction_factor
[1;32m      2[0m help(friction_factor)

File [0;32m/opt/hostedtoolcache/Python/3.11.9/x64/lib/python3.11/site-packages/particula/__init__.py:26[0m
[1;32m     23[0m __version__ [38;5;241m=[39m [38;5;124m"[39m[38;5;124m0.0.16[39m[38;5;124m"[39m
[1;32m     25[0m [38;5;66;03m# setup the logger[39;00m
[0;32m---> 26[0m logger [38;5;241m=[39m [43msetup[49m[43m([49m[43m)[49m
[1;32m     27[0m [38;5;66;03m# log the version of particula upon loading[39;00m
[1;32m     28[0m logger[38;5;241m.[39minfo([38;5;124m"[39m[38;5;124mparticula version [39m[38;5;132;01m%s[39;00m[38;5;124m loaded.[39m[38;5;124m"[39m, __version__)

File [0;32m/opt/hostedtoolcache/Python/3.11.9/x64/lib/python3.11/site-packages/particula/logger_setup.py:66[0m, in [0;36msetup[0;34m()[0m
[1;32m     64[0m os[38;5;241m.[39mmakedirs(logging_dir, exist_ok[38;5;241m=[39m[38;5;28;01mTrue[39;00m)
[1;32m     65[0m [38;5;66;03m# configure the logger[39;00m
[0;32m---> 66[0m [43mlogging[49m[38;5;241;43m.[39;49m[43mconfig[49m[38;5;241;43m.[39;49m[43mdictConfig[49m[43m([49m[43mconfig[49m[43m)[49m
[1;32m     67[0m [38;5;28;01mreturn[39;00m logger

File [0;32m/opt/hostedtoolcache/Python/3.11.9/x64/lib/python3.11/logging/config.py:823[0m, in [0;36mdictConfig[0;34m(config)[0m
[1;32m    821[0m [38;5;28;01mdef[39;00m [38;5;21mdictConfig[39m(config):
[1;32m    822[0m [38;5;250m    [39m[38;5;124;03m"""Configure logging using a dictionary."""[39;00m
[0;32m--> 823[0m     [43mdictConfigClass[49m[43m([49m[43mconfig[49m[43m)[49m[38;5;241;43m.[39;49m[43mconfigure[49m[43m([49m[43m)[49m

File [0;32m/opt/hostedtoolcache/Python/3.11.9/x64/lib/python3.11/logging/config.py:580[0m, in [0;36mDictConfigurator.configure[0;34m(self)[0m
[1;32m    578[0m             deferred[38;5;241m.[39mappend(name)
[1;32m    579[0m         [38;5;28;01melse[39;00m:
[0;32m--> 580[0m             [38;5;28;01mraise[39;00m [38;5;167;01mValueError[39;00m([38;5;124m'[39m[38;5;124mUnable to configure handler [39m[38;5;124m'[39m
[1;32m    581[0m                              [38;5;124m'[39m[38;5;132;01m%r[39;00m[38;5;124m'[39m [38;5;241m%[39m name) [38;5;28;01mfrom[39;00m [38;5;21;01me[39;00m
[1;32m    583[0m [38;5;66;03m# Now do any that were deferred[39;00m
[1;32m    584[0m [38;5;28;01mfor[39;00m name [38;5;129;01min[39;00m deferred:

[0;31mValueError[0m: Unable to configure handler 'file'

